<?xml version="1.0" ?>
<!-- =================================================================================== -->
<!-- |    This document was autogenerated by xacro from marty2.xacro                   | -->
<!-- |    EDITING THIS FILE BY HAND IS NOT RECOMMENDED                                 | -->
<!-- =================================================================================== -->
<robot name="marty2">
  <!-- Shared includes -->
  <!-- <xacro:include filename="$(find marty2_description)/urdf/marty2/marty2_params.xacro"/> -->
  <material name="blue">
    <color rgba="0.07 0.52 .625 1"/>
  </material>
  <material name="yellow">
    <color rgba=".8 .8 0 1"/>
  </material>
  <material name="white">
    <color rgba="1 1 1 1"/>
  </material>
  <link name="base_link"/>
  <!-- Main Structure -->
  <joint name="head_joint" type="fixed">
    <origin rpy="0 0 0" xyz="0 0 0"/>
    <parent link="base_link"/>
    <child link="head"/>
  </joint>
  <link name="head">
    <inertial>
      <mass value="1e-5"/>
      <origin rpy="0 0 0" xyz="0 0 0"/>
      <inertia ixx="1e-6" ixy="0" ixz="0" iyy="1e-6" iyz="0" izz="1e-6"/>
    </inertial>
    <visual>
      <geometry>
        <mesh filename="/alex/robotical/marty2_description/marty2_description/head.stl"/>
      </geometry>
      <origin rpy="0 0 0" xyz="0 0 0"/>
      <material name="blue">
        <color rgba="0.07 0.52 .625 1"/>
      </material>
    </visual>
    <collision>
      <geometry>
        <mesh filename="/path_to_meshes/head.stl"/>
      </geometry>
      <origin rpy="0 0 0" xyz="0 0 0"/>
      <material name="blue">
        <color rgba="0.07 0.52 .625 1"/>
      </material>
    </collision>
  </link>
  <joint name="side_panel_left_joint" type="fixed">
    <origin rpy="-0.0361 0 0" xyz="0.0025 0.05744  0.04221"/>
    <parent link="head"/>
    <child link="side_panel_left"/>
  </joint>
  <link name="side_panel_left">
    <inertial>
      <mass value="1e-5"/>
      <origin rpy="0 0 0" xyz="0 0 0"/>
      <inertia ixx="1e-6" ixy="0" ixz="0" iyy="1e-6" iyz="0" izz="1e-6"/>
    </inertial>
    <visual>
      <geometry>
        <mesh filename="/path_to_meshes/side_panel.stl"/>
      </geometry>
      <origin rpy="0 0 0" xyz="0 0 0"/>
      <material name="yellow">
        <color rgba=".8 .8 0 1"/>
      </material>
    </visual>
    <collision>
      <geometry>
        <mesh filename="/path_to_meshes/side_panel.stl"/>
      </geometry>
      <origin rpy="0 0 0" xyz="0 0 0"/>
      <material name="yellow">
        <color rgba=".8 .8 0 1"/>
      </material>
    </collision>
  </link>
  <joint name="side_panel_right_joint" type="fixed">
    <origin rpy="0.0361 0 0" xyz="0.0025 -0.05744 0.04221"/>
    <parent link="head"/>
    <child link="side_panel_right"/>
  </joint>
  <link name="side_panel_right">
    <inertial>
      <mass value="1e-5"/>
      <origin rpy="0 0 0" xyz="0 0 0"/>
      <inertia ixx="1e-6" ixy="0" ixz="0" iyy="1e-6" iyz="0" izz="1e-6"/>
    </inertial>
    <visual>
      <geometry>
        <mesh filename="/path_to_meshes/side_panel.stl"/>
      </geometry>
      <origin rpy="0 0 3.1416" xyz="0 0 0"/>
      <material name="yellow">
        <color rgba=".8 .8 0 1"/>
      </material>
    </visual>
    <collision>
      <geometry>
        <mesh filename="/path_to_meshes/side_panel.stl"/>
      </geometry>
      <origin rpy="0 0 3.1416" xyz="0 0 0"/>
      <material name="yellow">
        <color rgba=".8 .8 0 1"/>
      </material>
    </collision>
  </link>
  <!-- Eyes -->
  <joint name="eye_left_joint" type="revolute">
    <origin rpy="0 0 0" xyz="0.04570 0.02410 0.04671"/>
    <parent link="head"/>
    <child link="eye_left"/>
    <axis xyz="1 0 0"/>
    <limit effort="30" lower="-3.0" upper="0.25" velocity="6.29"/>
  </joint>
  <link name="eye_left">
    <inertial>
      <mass value="1e-5"/>
      <origin rpy="0 0 0" xyz="0 0 0"/>
      <inertia ixx="1e-6" ixy="0" ixz="0" iyy="1e-6" iyz="0" izz="1e-6"/>
    </inertial>
    <visual>
      <geometry>
        <mesh filename="/path_to_meshes/eye_left.stl"/>
      </geometry>
      <origin rpy="0 0 0" xyz="0 0 0"/>
      <material name="white">
        <color rgba="1 1 1 1"/>
      </material>
    </visual>
    <collision>
      <geometry>
        <mesh filename="/path_to_meshes/eye_left.stl"/>
      </geometry>
      <origin rpy="0 0 0" xyz="0 0 0"/>
      <material name="white">
        <color rgba="1 1 1 1"/>
      </material>
    </collision>
  </link>
  <joint name="eye_right_joint" type="revolute">
    <origin rpy="0 0 0" xyz="0.04570 -0.02410 0.04671"/>
    <parent link="head"/>
    <child link="eye_right"/>
    <axis xyz="1 0 0"/>
    <mimic joint="eye_left_joint" multiplier="-1"/>
    <limit effort="30" lower="-0.25" upper="3.0" velocity="6.29"/>
  </joint>
  <link name="eye_right">
    <inertial>
      <mass value="1e-5"/>
      <origin rpy="0 0 0" xyz="0 0 0"/>
      <inertia ixx="1e-6" ixy="0" ixz="0" iyy="1e-6" iyz="0" izz="1e-6"/>
    </inertial>
    <visual>
      <geometry>
        <mesh filename="/path_to_meshes/eye_right.stl"/>
      </geometry>
      <origin rpy="0.01 0 0" xyz="0 0 0"/>
      <material name="white">
        <color rgba="1 1 1 1"/>
      </material>
    </visual>
    <collision>
      <geometry>
        <mesh filename="/path_to_meshes/eye_right.stl"/>
      </geometry>
      <origin rpy="0.01 0 0" xyz="0 0 0"/>
      <material name="white">
        <color rgba="1 1 1 1"/>
      </material>
    </collision>
  </link>
  <!-- Left arm -->
  <joint name="arm_servo_gear_left_joint" type="revolute">
    <origin rpy="0 0 0" xyz="0 0.00025 0"/>
    <parent link="side_panel_left"/>
    <child link="arm_servo_gear_left"/>
    <axis xyz="0 1 0"/>
    <limit effort="30" lower="-0.95" upper="2.05" velocity="6.29"/>
  </joint>
  <link name="arm_servo_gear_left">
    <inertial>
      <mass value="1e-5"/>
      <origin rpy="0 0 0" xyz="0 0 0"/>
      <inertia ixx="1e-6" ixy="0" ixz="0" iyy="1e-6" iyz="0" izz="1e-6"/>
    </inertial>
    <visual>
      <geometry>
        <mesh filename="/path_to_meshes/arm_servo_gear.stl"/>
      </geometry>
      <origin rpy="0 -0.5585 0" xyz="0 0 0"/>
      <material name="yellow">
        <color rgba=".8 .8 0 1"/>
      </material>
    </visual>
    <collision>
      <geometry>
        <mesh filename="/path_to_meshes/arm_servo_gear.stl"/>
      </geometry>
      <origin rpy="0 -0.5585 0" xyz="0 0 0"/>
      <material name="yellow">
        <color rgba=".8 .8 0 1"/>
      </material>
    </collision>
  </link>
  <joint name="arm_left_joint" type="revolute">
    <origin rpy="0 0 0" xyz="0 0 -0.03020"/>
    <parent link="side_panel_left"/>
    <child link="arm_left"/>
    <axis xyz="0 1 0"/>
    <mimic joint="arm_servo_gear_left_joint" multiplier="-1.307692308"/>
    <limit effort="30" lower="-2.68" upper="1.24" velocity="6.29"/>
  </joint>
  <link name="arm_left">
    <inertial>
      <mass value="1e-5"/>
      <origin rpy="0 0 0" xyz="0 0 0"/>
      <inertia ixx="1e-6" ixy="0" ixz="0" iyy="1e-6" iyz="0" izz="1e-6"/>
    </inertial>
    <visual>
      <geometry>
        <mesh filename="/path_to_meshes/arm.stl"/>
      </geometry>
      <origin rpy="0 0 0" xyz="0 0 0"/>
      <material name="yellow">
        <color rgba=".8 .8 0 1"/>
      </material>
    </visual>
    <collision>
      <geometry>
        <mesh filename="/path_to_meshes/arm.stl"/>
      </geometry>
      <origin rpy="0 0 0" xyz="0 0 0"/>
      <material name="yellow">
        <color rgba=".8 .8 0 1"/>
      </material>
    </collision>
  </link>
  <joint name="hand_left_joint" type="fixed">
    <origin rpy="0.3490658504 0 0" xyz="0.00000 0.0330 -0.05539"/>
    <parent link="arm_left"/>
    <child link="hand_left"/>
  </joint>
  <link name="hand_left">
    <inertial>
      <mass value="1e-5"/>
      <origin rpy="0 0 0" xyz="0 0 0"/>
      <inertia ixx="1e-6" ixy="0" ixz="0" iyy="1e-6" iyz="0" izz="1e-6"/>
    </inertial>
    <visual>
      <geometry>
        <mesh filename="/path_to_meshes/hand.stl"/>
      </geometry>
      <origin rpy="0 0 0" xyz="0 0 0"/>
      <material name="yellow">
        <color rgba=".8 .8 0 1"/>
      </material>
    </visual>
    <collision>
      <geometry>
        <mesh filename="/path_to_meshes/hand.stl"/>
      </geometry>
      <origin rpy="0 0 0" xyz="0 0 0"/>
      <material name="yellow">
        <color rgba=".8 .8 0 1"/>
      </material>
    </collision>
  </link>
  <!-- Right arm -->
  <joint name="arm_servo_gear_right_joint" type="revolute">
    <origin rpy="0 0 0" xyz="0 -0.00025 0"/>
    <parent link="side_panel_right"/>
    <child link="arm_servo_gear_right"/>
    <axis xyz="0 1 0"/>
    <limit effort="30" lower="-0.95" upper="2.05" velocity="6.29"/>
  </joint>
  <link name="arm_servo_gear_right">
    <inertial>
      <mass value="1e-5"/>
      <origin rpy="0 0 0" xyz="0 0 0"/>
      <inertia ixx="1e-6" ixy="0" ixz="0" iyy="1e-6" iyz="0" izz="1e-6"/>
    </inertial>
    <visual>
      <geometry>
        <mesh filename="/path_to_meshes/arm_servo_gear.stl"/>
      </geometry>
      <origin rpy="0 0.5585 3.1416" xyz="0 0 0"/>
      <material name="yellow">
        <color rgba=".8 .8 0 1"/>
      </material>
    </visual>
    <collision>
      <geometry>
        <mesh filename="/path_to_meshes/arm_servo_gear.stl"/>
      </geometry>
      <origin rpy="0 0.5585 3.1416" xyz="0 0 0"/>
      <material name="yellow">
        <color rgba=".8 .8 0 1"/>
      </material>
    </collision>
  </link>
  <joint name="arm_right_joint" type="revolute">
    <origin rpy="0 0 0" xyz="0 0 -0.03020"/>
    <parent link="side_panel_right"/>
    <child link="arm_right"/>
    <axis xyz="0 1 0"/>
    <mimic joint="arm_servo_gear_right_joint" multiplier="-1.307692308"/>
    <limit effort="30" lower="-2.68" upper="1.24" velocity="6.29"/>
  </joint>
  <link name="arm_right">
    <inertial>
      <mass value="1e-5"/>
      <origin rpy="0 0 0" xyz="0 0 0"/>
      <inertia ixx="1e-6" ixy="0" ixz="0" iyy="1e-6" iyz="0" izz="1e-6"/>
    </inertial>
    <visual>
      <geometry>
        <mesh filename="/path_to_meshes/arm.stl"/>
      </geometry>
      <origin rpy="0 0 3.1416" xyz="0 0 0"/>
      <material name="yellow">
        <color rgba=".8 .8 0 1"/>
      </material>
    </visual>
    <collision>
      <geometry>
        <mesh filename="/path_to_meshes/arm.stl"/>
      </geometry>
      <origin rpy="0 0 3.1416" xyz="0 0 0"/>
      <material name="yellow">
        <color rgba=".8 .8 0 1"/>
      </material>
    </collision>
  </link>
  <joint name="hand_right_joint" type="fixed">
    <origin rpy="-0.3490658504 0 0" xyz="0.00000 -0.0330 -0.05539"/>
    <parent link="arm_right"/>
    <child link="hand_right"/>
  </joint>
  <link name="hand_right">
    <inertial>
      <mass value="1e-5"/>
      <origin rpy="0 0 0" xyz="0 0 0"/>
      <inertia ixx="1e-6" ixy="0" ixz="0" iyy="1e-6" iyz="0" izz="1e-6"/>
    </inertial>
    <visual>
      <geometry>
        <mesh filename="/path_to_meshes/hand.stl"/>
      </geometry>
      <origin rpy="0 0 0" xyz="0 0 0"/>
      <material name="yellow">
        <color rgba=".8 .8 0 1"/>
      </material>
    </visual>
    <collision>
      <geometry>
        <mesh filename="/path_to_meshes/hand.stl"/>
      </geometry>
      <origin rpy="0 0 0" xyz="0 0 0"/>
      <material name="yellow">
        <color rgba=".8 .8 0 1"/>
      </material>
    </collision>
  </link>
  <!-- Left leg -->
  <joint name="hip_left_joint" type="fixed">
    <origin rpy="0.0000 0.0000 0.0000" xyz="0.01087 0.04709 -0.01465"/>
    <parent link="head"/>
    <child link="hip_left"/>
  </joint>
  <link name="hip_left">
    <inertial>
      <mass value="1e-5"/>
      <origin rpy="0 0 0" xyz="0 0 0"/>
      <inertia ixx="1e-6" ixy="0" ixz="0" iyy="1e-6" iyz="0" izz="1e-6"/>
    </inertial>
    <visual>
      <geometry>
        <mesh filename="/path_to_meshes/hip.stl"/>
      </geometry>
      <origin rpy="0 0 0" xyz="0 0 0"/>
      <material name="blue">
        <color rgba="0.07 0.52 .625 1"/>
      </material>
    </visual>
    <collision>
      <geometry>
        <mesh filename="/path_to_meshes/hip.stl"/>
      </geometry>
      <origin rpy="0 0 0" xyz="0 0 0"/>
      <material name="blue">
        <color rgba="0.07 0.52 .625 1"/>
      </material>
    </collision>
  </link>
  <joint name="leg_left_thigh_front_joint" type="revolute">
    <origin rpy="0.0000 0.0000 0.0000" xyz="0.00000  0.00025 0.00000"/>
    <parent link="hip_left"/>
    <child link="leg_left_thigh_front"/>
    <axis xyz="0 1 0"/>
    <limit effort="30" lower="-1.0" upper="1.0" velocity="6.29"/>
  </joint>
  <link name="leg_left_thigh_front">
    <inertial>
      <mass value="1e-5"/>
      <origin rpy="0 0 0" xyz="0 0 0"/>
      <inertia ixx="1e-6" ixy="0" ixz="0" iyy="1e-6" iyz="0" izz="1e-6"/>
    </inertial>
    <visual>
      <geometry>
        <mesh filename="/path_to_meshes/thigh.stl"/>
      </geometry>
      <origin rpy="0 0 0" xyz="0 0 0"/>
      <material name="blue">
        <color rgba="0.07 0.52 .625 1"/>
      </material>
    </visual>
    <collision>
      <geometry>
        <mesh filename="/path_to_meshes/thigh.stl"/>
      </geometry>
      <origin rpy="0 0 0" xyz="0 0 0"/>
      <material name="blue">
        <color rgba="0.07 0.52 .625 1"/>
      </material>
    </collision>
  </link>
  <joint name="leg_left_thigh_back_joint" type="revolute">
    <origin rpy="0.0000 0.0000 0.0000" xyz="-0.01620 -0.03795  0.00000"/>
    <parent link="hip_left"/>
    <child link="leg_left_thigh_back"/>
    <axis xyz="0 1 0"/>
    <mimic joint="leg_left_thigh_front_joint" multiplier="1"/>
    <limit effort="30" lower="-1.0" upper="1.0" velocity="6.29"/>
  </joint>
  <link name="leg_left_thigh_back">
    <inertial>
      <mass value="1e-5"/>
      <origin rpy="0 0 0" xyz="0 0 0"/>
      <inertia ixx="1e-6" ixy="0" ixz="0" iyy="1e-6" iyz="0" izz="1e-6"/>
    </inertial>
    <visual>
      <geometry>
        <mesh filename="/path_to_meshes/thigh.stl"/>
      </geometry>
      <origin rpy="0 0 3.1416" xyz="0 0 0"/>
      <material name="blue">
        <color rgba="0.07 0.52 .625 1"/>
      </material>
    </visual>
    <collision>
      <geometry>
        <mesh filename="/path_to_meshes/thigh.stl"/>
      </geometry>
      <origin rpy="0 0 3.1416" xyz="0 0 0"/>
      <material name="blue">
        <color rgba="0.07 0.52 .625 1"/>
      </material>
    </collision>
  </link>
  <joint name="leg_left_knee_upper_joint" type="revolute">
    <origin rpy="0.0000 0.0000 0.0000" xyz="0.00000  -0.00015  -0.05000"/>
    <parent link="leg_left_thigh_front"/>
    <child link="leg_left_knee_upper"/>
    <axis xyz="0 1 0"/>
    <mimic joint="leg_left_thigh_front_joint" multiplier="-1"/>
    <limit effort="30" lower="-1.0" upper="1.0" velocity="6.29"/>
  </joint>
  <link name="leg_left_knee_upper">
    <inertial>
      <mass value="1e-5"/>
      <origin rpy="0 0 0" xyz="0 0 0"/>
      <inertia ixx="1e-6" ixy="0" ixz="0" iyy="1e-6" iyz="0" izz="1e-6"/>
    </inertial>
    <visual>
      <geometry>
        <mesh filename="/path_to_meshes/knee_upper.stl"/>
      </geometry>
      <origin rpy="0 0 0" xyz="0 0 0"/>
      <material name="blue">
        <color rgba="0.07 0.52 .625 1"/>
      </material>
    </visual>
    <collision>
      <geometry>
        <mesh filename="/path_to_meshes/knee_upper.stl"/>
      </geometry>
      <origin rpy="0 0 0" xyz="0 0 0"/>
      <material name="blue">
        <color rgba="0.07 0.52 .625 1"/>
      </material>
    </collision>
  </link>
  <joint name="leg_left_twist_upper_joint" type="fixed">
    <origin rpy="0.0000 0.0000 0.0000" xyz="-0.00810 -0.01885  -0.00968"/>
    <parent link="leg_left_knee_upper"/>
    <child link="leg_left_twist_upper"/>
  </joint>
  <link name="leg_left_twist_upper">
    <inertial>
      <mass value="1e-5"/>
      <origin rpy="0 0 0" xyz="0 0 0"/>
      <inertia ixx="1e-6" ixy="0" ixz="0" iyy="1e-6" iyz="0" izz="1e-6"/>
    </inertial>
    <visual>
      <geometry>
        <mesh filename="/path_to_meshes/twist_upper.stl"/>
      </geometry>
      <origin rpy="0 0 0" xyz="0 0 0"/>
      <material name="yellow">
        <color rgba=".8 .8 0 1"/>
      </material>
    </visual>
    <collision>
      <geometry>
        <mesh filename="/path_to_meshes/twist_upper.stl"/>
      </geometry>
      <origin rpy="0 0 0" xyz="0 0 0"/>
      <material name="yellow">
        <color rgba=".8 .8 0 1"/>
      </material>
    </collision>
  </link>
  <joint name="leg_left_twist_lower_joint" type="revolute">
    <origin rpy="0.0000 0.0000 0.0000" xyz="0.0000 0.0000 0.0000"/>
    <parent link="leg_left_twist_upper"/>
    <child link="leg_left_twist_lower"/>
    <axis xyz="0 0 1"/>
    <limit effort="30" lower="-1.0" upper="1.0" velocity="6.29"/>
  </joint>
  <link name="leg_left_twist_lower">
    <inertial>
      <mass value="1e-5"/>
      <origin rpy="0 0 0" xyz="0 0 0"/>
      <inertia ixx="1e-6" ixy="0" ixz="0" iyy="1e-6" iyz="0" izz="1e-6"/>
    </inertial>
    <visual>
      <geometry>
        <mesh filename="/path_to_meshes/twist_lower.stl"/>
      </geometry>
      <origin rpy="0 0 0" xyz="0 0 0"/>
      <material name="yellow">
        <color rgba=".8 .8 0 1"/>
      </material>
    </visual>
    <collision>
      <geometry>
        <mesh filename="/path_to_meshes/twist_lower.stl"/>
      </geometry>
      <origin rpy="0 0 0" xyz="0 0 0"/>
      <material name="yellow">
        <color rgba=".8 .8 0 1"/>
      </material>
    </collision>
  </link>
  <joint name="leg_left_knee_lower_joint" type="fixed">
    <origin rpy="0.0000 0.0000 0.0000" xyz="-0.01885 0.00810 -0.02075"/>
    <parent link="leg_left_twist_lower"/>
    <child link="leg_left_knee_lower"/>
  </joint>
  <link name="leg_left_knee_lower">
    <inertial>
      <mass value="1e-5"/>
      <origin rpy="0 0 0" xyz="0 0 0"/>
      <inertia ixx="1e-6" ixy="0" ixz="0" iyy="1e-6" iyz="0" izz="1e-6"/>
    </inertial>
    <visual>
      <geometry>
        <mesh filename="/path_to_meshes/knee_lower.stl"/>
      </geometry>
      <origin rpy="0 0 0" xyz="0 0 0"/>
      <material name="blue">
        <color rgba="0.07 0.52 .625 1"/>
      </material>
    </visual>
    <collision>
      <geometry>
        <mesh filename="/path_to_meshes/knee_lower.stl"/>
      </geometry>
      <origin rpy="0 0 0" xyz="0 0 0"/>
      <material name="blue">
        <color rgba="0.07 0.52 .625 1"/>
      </material>
    </collision>
  </link>
  <joint name="leg_left_shin_exterior_joint" type="revolute">
    <origin rpy="0.0000 0.0000 0.0000" xyz="0.0000 0.0000 0.0000"/>
    <parent link="leg_left_knee_lower"/>
    <child link="leg_left_shin_exterior"/>
    <axis xyz="1 0 0"/>
    <limit effort="30" lower="-1.0" upper="1.0" velocity="6.29"/>
  </joint>
  <link name="leg_left_shin_exterior">
    <inertial>
      <mass value="1e-5"/>
      <origin rpy="0 0 0" xyz="0 0 0"/>
      <inertia ixx="1e-6" ixy="0" ixz="0" iyy="1e-6" iyz="0" izz="1e-6"/>
    </inertial>
    <visual>
      <geometry>
        <mesh filename="/path_to_meshes/shin.stl"/>
      </geometry>
      <origin rpy="0 0 0" xyz="0 0 0"/>
      <material name="blue">
        <color rgba="0.07 0.52 .625 1"/>
      </material>
    </visual>
    <collision>
      <geometry>
        <mesh filename="/path_to_meshes/shin.stl"/>
      </geometry>
      <origin rpy="0 0 0" xyz="0 0 0"/>
      <material name="blue">
        <color rgba="0.07 0.52 .625 1"/>
      </material>
    </collision>
  </link>
  <joint name="leg_left_shin_interior_joint" type="revolute">
    <origin rpy="0.0000 0.0000 0.0000" xyz="0.03770  -0.01620  0.00000"/>
    <parent link="leg_left_knee_lower"/>
    <child link="leg_left_shin_interior"/>
    <axis xyz="1 0 0"/>
    <mimic joint="leg_left_shin_exterior_joint" multiplier="1"/>
    <limit effort="30" lower="-1.0" upper="1.0" velocity="6.29"/>
  </joint>
  <link name="leg_left_shin_interior">
    <inertial>
      <mass value="1e-5"/>
      <origin rpy="0 0 0" xyz="0 0 0"/>
      <inertia ixx="1e-6" ixy="0" ixz="0" iyy="1e-6" iyz="0" izz="1e-6"/>
    </inertial>
    <visual>
      <geometry>
        <mesh filename="/path_to_meshes/shin.stl"/>
      </geometry>
      <origin rpy="0 0 3.1416" xyz="0 0 0"/>
      <material name="blue">
        <color rgba="0.07 0.52 .625 1"/>
      </material>
    </visual>
    <collision>
      <geometry>
        <mesh filename="/path_to_meshes/shin.stl"/>
      </geometry>
      <origin rpy="0 0 3.1416" xyz="0 0 0"/>
      <material name="blue">
        <color rgba="0.07 0.52 .625 1"/>
      </material>
    </collision>
  </link>
  <joint name="foot_left_joint" type="revolute">
    <origin rpy="0.0000 0.0000 0.0000" xyz="0.00000  0.00000 -0.05000"/>
    <parent link="leg_left_shin_exterior"/>
    <child link="foot_left"/>
    <axis xyz="1 0 0"/>
    <mimic joint="leg_left_shin_exterior_joint" multiplier="-1"/>
    <limit effort="30" lower="-1.0" upper="1.0" velocity="6.29"/>
  </joint>
  <link name="foot_left">
    <inertial>
      <mass value="1e-5"/>
      <origin rpy="0 0 0" xyz="0 0 0"/>
      <inertia ixx="1e-6" ixy="0" ixz="0" iyy="1e-6" iyz="0" izz="1e-6"/>
    </inertial>
    <visual>
      <geometry>
        <mesh filename="/path_to_meshes/foot.stl"/>
      </geometry>
      <origin rpy="0 0 0" xyz="0 0 0"/>
      <material name="yellow">
        <color rgba=".8 .8 0 1"/>
      </material>
    </visual>
    <collision>
      <geometry>
        <mesh filename="/path_to_meshes/foot.stl"/>
      </geometry>
      <origin rpy="0 0 0" xyz="0 0 0"/>
      <material name="yellow">
        <color rgba=".8 .8 0 1"/>
      </material>
    </collision>
  </link>
  <!-- Right leg -->
  <joint name="hip_right_joint" type="fixed">
    <origin rpy="0.0000 0.0000 0.0000" xyz="0.01087 -0.00941 -0.01465"/>
    <parent link="head"/>
    <child link="hip_right"/>
  </joint>
  <link name="hip_right">
    <inertial>
      <mass value="1e-5"/>
      <origin rpy="0 0 0" xyz="0 0 0"/>
      <inertia ixx="1e-6" ixy="0" ixz="0" iyy="1e-6" iyz="0" izz="1e-6"/>
    </inertial>
    <visual>
      <geometry>
        <mesh filename="/path_to_meshes/hip.stl"/>
      </geometry>
      <origin rpy="0 0 0" xyz="0 0 0"/>
      <material name="blue">
        <color rgba="0.07 0.52 .625 1"/>
      </material>
    </visual>
    <collision>
      <geometry>
        <mesh filename="/path_to_meshes/hip.stl"/>
      </geometry>
      <origin rpy="0 0 0" xyz="0 0 0"/>
      <material name="blue">
        <color rgba="0.07 0.52 .625 1"/>
      </material>
    </collision>
  </link>
  <joint name="leg_right_thigh_front_joint" type="revolute">
    <origin rpy="0.0000 0.0000 0.0000" xyz="0.00000  0.00025 0.00000"/>
    <parent link="hip_right"/>
    <child link="leg_right_thigh_front"/>
    <axis xyz="0 1 0"/>
    <limit effort="30" lower="-1.0" upper="1.0" velocity="6.29"/>
  </joint>
  <link name="leg_right_thigh_front">
    <inertial>
      <mass value="1e-5"/>
      <origin rpy="0 0 0" xyz="0 0 0"/>
      <inertia ixx="1e-6" ixy="0" ixz="0" iyy="1e-6" iyz="0" izz="1e-6"/>
    </inertial>
    <visual>
      <geometry>
        <mesh filename="/path_to_meshes/thigh.stl"/>
      </geometry>
      <origin rpy="0 0 0" xyz="0 0 0"/>
      <material name="blue">
        <color rgba="0.07 0.52 .625 1"/>
      </material>
    </visual>
    <collision>
      <geometry>
        <mesh filename="/path_to_meshes/thigh.stl"/>
      </geometry>
      <origin rpy="0 0 0" xyz="0 0 0"/>
      <material name="blue">
        <color rgba="0.07 0.52 .625 1"/>
      </material>
    </collision>
  </link>
  <joint name="leg_right_thigh_back_joint" type="revolute">
    <origin rpy="0.0000 0.0000 0.0000" xyz="-0.01620 -0.03795  0.00000"/>
    <parent link="hip_right"/>
    <child link="leg_right_thigh_back"/>
    <axis xyz="0 1 0"/>
    <mimic joint="leg_right_thigh_front_joint" multiplier="1"/>
    <limit effort="30" lower="-1.0" upper="1.0" velocity="6.29"/>
  </joint>
  <link name="leg_right_thigh_back">
    <inertial>
      <mass value="1e-5"/>
      <origin rpy="0 0 0" xyz="0 0 0"/>
      <inertia ixx="1e-6" ixy="0" ixz="0" iyy="1e-6" iyz="0" izz="1e-6"/>
    </inertial>
    <visual>
      <geometry>
        <mesh filename="/path_to_meshes/thigh.stl"/>
      </geometry>
      <origin rpy="0 0 3.1416" xyz="0 0 0"/>
      <material name="blue">
        <color rgba="0.07 0.52 .625 1"/>
      </material>
    </visual>
    <collision>
      <geometry>
        <mesh filename="/path_to_meshes/thigh.stl"/>
      </geometry>
      <origin rpy="0 0 3.1416" xyz="0 0 0"/>
      <material name="blue">
        <color rgba="0.07 0.52 .625 1"/>
      </material>
    </collision>
  </link>
  <joint name="leg_right_knee_upper_joint" type="revolute">
    <origin rpy="0.0000 0.0000 0.0000" xyz="0.00000  -0.00015  -0.05000"/>
    <parent link="leg_right_thigh_front"/>
    <child link="leg_right_knee_upper"/>
    <axis xyz="0 1 0"/>
    <mimic joint="leg_right_thigh_front_joint" multiplier="-1"/>
    <limit effort="30" lower="-1.0" upper="1.0" velocity="6.29"/>
  </joint>
  <link name="leg_right_knee_upper">
    <inertial>
      <mass value="1e-5"/>
      <origin rpy="0 0 0" xyz="0 0 0"/>
      <inertia ixx="1e-6" ixy="0" ixz="0" iyy="1e-6" iyz="0" izz="1e-6"/>
    </inertial>
    <visual>
      <geometry>
        <mesh filename="/path_to_meshes/knee_upper.stl"/>
      </geometry>
      <origin rpy="0 0 0" xyz="0 0 0"/>
      <material name="blue">
        <color rgba="0.07 0.52 .625 1"/>
      </material>
    </visual>
    <collision>
      <geometry>
        <mesh filename="/path_to_meshes/knee_upper.stl"/>
      </geometry>
      <origin rpy="0 0 0" xyz="0 0 0"/>
      <material name="blue">
        <color rgba="0.07 0.52 .625 1"/>
      </material>
    </collision>
  </link>
  <joint name="leg_right_twist_upper_joint" type="fixed">
    <origin rpy="0.0000 0.0000 0.0000" xyz="-0.00810 -0.01885  -0.00968"/>
    <parent link="leg_right_knee_upper"/>
    <child link="leg_right_twist_upper"/>
  </joint>
  <link name="leg_right_twist_upper">
    <inertial>
      <mass value="1e-5"/>
      <origin rpy="0 0 0" xyz="0 0 0"/>
      <inertia ixx="1e-6" ixy="0" ixz="0" iyy="1e-6" iyz="0" izz="1e-6"/>
    </inertial>
    <visual>
      <geometry>
        <mesh filename="/path_to_meshes/twist_upper.stl"/>
      </geometry>
      <origin rpy="0 0 0" xyz="0 0 0"/>
      <material name="yellow">
        <color rgba=".8 .8 0 1"/>
      </material>
    </visual>
    <collision>
      <geometry>
        <mesh filename="/path_to_meshes/twist_upper.stl"/>
      </geometry>
      <origin rpy="0 0 0" xyz="0 0 0"/>
      <material name="yellow">
        <color rgba=".8 .8 0 1"/>
      </material>
    </collision>
  </link>
  <joint name="leg_right_twist_lower_joint" type="revolute">
    <origin rpy="0.0000 0.0000 0.0000" xyz="0.0000 0.0000 0.0000"/>
    <parent link="leg_right_twist_upper"/>
    <child link="leg_right_twist_lower"/>
    <axis xyz="0 0 1"/>
    <limit effort="30" lower="-1.0" upper="1.0" velocity="6.29"/>
  </joint>
  <link name="leg_right_twist_lower">
    <inertial>
      <mass value="1e-5"/>
      <origin rpy="0 0 0" xyz="0 0 0"/>
      <inertia ixx="1e-6" ixy="0" ixz="0" iyy="1e-6" iyz="0" izz="1e-6"/>
    </inertial>
    <visual>
      <geometry>
        <mesh filename="/path_to_meshes/twist_lower.stl"/>
      </geometry>
      <origin rpy="0 0 0" xyz="0 0 0"/>
      <material name="yellow">
        <color rgba=".8 .8 0 1"/>
      </material>
    </visual>
    <collision>
      <geometry>
        <mesh filename="/path_to_meshes/twist_lower.stl"/>
      </geometry>
      <origin rpy="0 0 0" xyz="0 0 0"/>
      <material name="yellow">
        <color rgba=".8 .8 0 1"/>
      </material>
    </collision>
  </link>
  <joint name="leg_right_knee_lower_joint" type="fixed">
    <origin rpy="0.0000 0.0000 0.0000" xyz="-0.01885 0.00810 -0.02075"/>
    <parent link="leg_right_twist_lower"/>
    <child link="leg_right_knee_lower"/>
  </joint>
  <link name="leg_right_knee_lower">
    <inertial>
      <mass value="1e-5"/>
      <origin rpy="0 0 0" xyz="0 0 0"/>
      <inertia ixx="1e-6" ixy="0" ixz="0" iyy="1e-6" iyz="0" izz="1e-6"/>
    </inertial>
    <visual>
      <geometry>
        <mesh filename="/path_to_meshes/knee_lower.stl"/>
      </geometry>
      <origin rpy="0 0 0" xyz="0 0 0"/>
      <material name="blue">
        <color rgba="0.07 0.52 .625 1"/>
      </material>
    </visual>
    <collision>
      <geometry>
        <mesh filename="/path_to_meshes/knee_lower.stl"/>
      </geometry>
      <origin rpy="0 0 0" xyz="0 0 0"/>
      <material name="blue">
        <color rgba="0.07 0.52 .625 1"/>
      </material>
    </collision>
  </link>
  <joint name="leg_right_shin_exterior_joint" type="revolute">
    <origin rpy="0.0000 0.0000 0.0000" xyz="0.03770  -0.01620  0.00000"/>
    <parent link="leg_right_knee_lower"/>
    <child link="leg_right_shin_exterior"/>
    <axis xyz="1 0 0"/>
    <mimic joint="leg_right_shin_interior_joint" multiplier="1"/>
    <limit effort="30" lower="-1.0" upper="1.0" velocity="6.29"/>
  </joint>
  <link name="leg_right_shin_exterior">
    <inertial>
      <mass value="1e-5"/>
      <origin rpy="0 0 0" xyz="0 0 0"/>
      <inertia ixx="1e-6" ixy="0" ixz="0" iyy="1e-6" iyz="0" izz="1e-6"/>
    </inertial>
    <visual>
      <geometry>
        <mesh filename="/path_to_meshes/shin.stl"/>
      </geometry>
      <origin rpy="0 0 3.1416" xyz="0 0 0"/>
      <material name="blue">
        <color rgba="0.07 0.52 .625 1"/>
      </material>
    </visual>
    <collision>
      <geometry>
        <mesh filename="/path_to_meshes/shin.stl"/>
      </geometry>
      <origin rpy="0 0 3.1416" xyz="0 0 0"/>
      <material name="blue">
        <color rgba="0.07 0.52 .625 1"/>
      </material>
    </collision>
  </link>
  <joint name="leg_right_shin_interior_joint" type="revolute">
    <origin rpy="0.0000 0.0000 0.0000" xyz="0.0000 0.0000 0.0000"/>
    <parent link="leg_right_knee_lower"/>
    <child link="leg_right_shin_interior"/>
    <axis xyz="1 0 0"/>
    <limit effort="30" lower="-1.0" upper="1.0" velocity="6.29"/>
  </joint>
  <link name="leg_right_shin_interior">
    <inertial>
      <mass value="1e-5"/>
      <origin rpy="0 0 0" xyz="0 0 0"/>
      <inertia ixx="1e-6" ixy="0" ixz="0" iyy="1e-6" iyz="0" izz="1e-6"/>
    </inertial>
    <visual>
      <geometry>
        <mesh filename="/path_to_meshes/shin.stl"/>
      </geometry>
      <origin rpy="0 0 0" xyz="0 0 0"/>
      <material name="blue">
        <color rgba="0.07 0.52 .625 1"/>
      </material>
    </visual>
    <collision>
      <geometry>
        <mesh filename="/path_to_meshes/shin.stl"/>
      </geometry>
      <origin rpy="0 0 0" xyz="0 0 0"/>
      <material name="blue">
        <color rgba="0.07 0.52 .625 1"/>
      </material>
    </collision>
  </link>
  <joint name="foot_right_joint" type="revolute">
    <origin rpy="0.0000 0.0000 0.0000" xyz="0 0 -0.05000"/>
    <parent link="leg_right_shin_interior"/>
    <child link="foot_right"/>
    <axis xyz="1 0 0"/>
    <mimic joint="leg_right_shin_interior_joint" multiplier="-1"/>
    <limit effort="30" lower="-1.0" upper="1.0" velocity="6.29"/>
  </joint>
  <link name="foot_right">
    <inertial>
      <mass value="1e-5"/>
      <origin rpy="0 0 0" xyz="0 0 0"/>
      <inertia ixx="1e-6" ixy="0" ixz="0" iyy="1e-6" iyz="0" izz="1e-6"/>
    </inertial>
    <visual>
      <geometry>
        <mesh filename="/path_to_meshes/foot.stl"/>
      </geometry>
      <origin rpy="0 0 3.1416" xyz="0.0379 -0.0162 0"/>
      <material name="yellow">
        <color rgba=".8 .8 0 1"/>
      </material>
    </visual>
    <collision>
      <geometry>
        <mesh filename="/path_to_meshes/foot.stl"/>
      </geometry>
      <origin rpy="0 0 3.1416" xyz="0.0379 -0.0162 0"/>
      <material name="yellow">
        <color rgba=".8 .8 0 1"/>
      </material>
    </collision>
  </link>
  <!-- Bolt-on sensors go here -->
  <!-- <xacro:include filename="$(find marty2_description)/urdf/marty2/marty2_sensors.xacro"/> -->
  <ros2_control name="marty2" type="system">
    <hardware>
      <plugin>mock_components/GenericSystem</plugin>
      <param name="calculate_dynamics">false</param>
      <param name="custom_interface_with_following_offset"/>
      <param name="disable_commands">false</param>
      <param name="mock_gpio_commands">false</param>
      <param name="mock_sensor_commands">false</param>
      <param name="position_state_following_offset">0.0</param>
    </hardware>
    <joint name="eye_left_joint">
      <command_interface name="position">
        <param name="min">-1</param>
        <param name="max">1</param>
      </command_interface>
      <state_interface name="position"/>
    </joint>
    <joint name="arm_servo_gear_left_joint">
      <command_interface name="position">
        <param name="min">-1</param>
        <param name="max">1</param>
      </command_interface>
      <state_interface name="position"/>
    </joint>
    <joint name="arm_servo_gear_right_joint">
      <command_interface name="position">
        <param name="min">-1</param>
        <param name="max">1</param>
      </command_interface>
      <state_interface name="position"/>
    </joint>
    <joint name="leg_left_thigh_front_joint">
      <command_interface name="position">
        <param name="min">-1</param>
        <param name="max">1</param>
      </command_interface>
      <state_interface name="position"/>
    </joint>
    <joint name="leg_right_thigh_front_joint">
      <command_interface name="position">
        <param name="min">-1</param>
        <param name="max">1</param>
      </command_interface>
      <state_interface name="position"/>
    </joint>
    <joint name="leg_left_twist_lower_joint">
      <command_interface name="position">
        <param name="min">-1</param>
        <param name="max">1</param>
      </command_interface>
      <state_interface name="position"/>
    </joint>
    <joint name="leg_right_twist_lower_joint">
      <command_interface name="position">
        <param name="min">-1</param>
        <param name="max">1</param>
      </command_interface>
      <state_interface name="position"/>
    </joint>
    <joint name="leg_left_shin_exterior_joint">
      <command_interface name="position">
        <param name="min">-1</param>
        <param name="max">1</param>
      </command_interface>
      <state_interface name="position"/>
    </joint>
    <joint name="leg_right_shin_interior_joint">
      <command_interface name="position">
        <param name="min">-1</param>
        <param name="max">1</param>
      </command_interface>
      <state_interface name="position"/>
    </joint>
  </ros2_control>
</robot>
